<?xml version="1.0" ?>
<!-- =================================================================================== -->
<!-- |    This document was autogenerated by xacro from phantomx.xacro                 | -->
<!-- |    EDITING THIS FILE BY HAND IS NOT RECOMMENDED                                 | -->
<!-- =================================================================================== -->
<robot name="phantomx_arm" xmlns:xacro="http://ros.org/wiki/xacro">
  <transmission name="tran1">
    <type>transmission_interface/SimpleTransmission</type>
    <joint name="joint_1"/>
    <actuator name="motor1">
      <hardwareInterface>EffortJointInterface</hardwareInterface>
      <mechanicalReduction>1</mechanicalReduction>
    </actuator>
  </transmission>
  <transmission name="tran2">
    <type>transmission_interface/SimpleTransmission</type>
    <joint name="joint_2"/>
    <actuator name="motor2">
      <hardwareInterface>EffortJointInterface</hardwareInterface>
      <mechanicalReduction>1</mechanicalReduction>
    </actuator>
  </transmission>
  <transmission name="tran3">
    <type>transmission_interface/SimpleTransmission</type>
    <joint name="joint_3"/>
    <actuator name="motor3">
      <hardwareInterface>EffortJointInterface</hardwareInterface>
      <mechanicalReduction>1</mechanicalReduction>
    </actuator>
  </transmission>
  <transmission name="tran4">
    <type>transmission_interface/SimpleTransmission</type>
    <joint name="joint_4"/>
    <actuator name="motor4">
      <hardwareInterface>EffortJointInterface</hardwareInterface>
      <mechanicalReduction>1</mechanicalReduction>
    </actuator>
  </transmission>
  <transmission name="tran5">
    <type>transmission_interface/SimpleTransmission</type>
    <joint name="joint_6"/>
    <actuator name="motor5">
      <hardwareInterface>EffortJointInterface</hardwareInterface>
      <mechanicalReduction>1</mechanicalReduction>
    </actuator>
  </transmission>
  <transmission name="tran6">
    <type>transmission_interface/SimpleTransmission</type>
    <joint name="joint_7"/>
    <actuator name="motor6">
      <hardwareInterface>EffortJointInterface</hardwareInterface>
      <mechanicalReduction>1</mechanicalReduction>
    </actuator>
  </transmission>
  <link name="arm_base_link">
    <visual>
      <origin rpy="0.0 0.0 3.14159" xyz="0.1 0.1 0.0"/>
      <geometry>
        <mesh filename="package://phantomx_arm_description/meshes/visual/base_link.stl" scale="0.01 0.01 0.01"/>
      </geometry>
      <material name="">
        <color rgba="0.15 0.15 0.15 1.0"/>
      </material>
    </visual>
    <collision>
      <origin rpy="0 0 0" xyz="0 0 0"/>
      <geometry>
        <mesh filename="package://phantomx_arm_description/meshes/collision/base_link.stl" scale="0.01 0.01 0.01"/>
      </geometry>
    </collision>
    <inertial>
      <origin rpy="0 0 0" xyz="0 0 0"/>
      <mass value="1"/>
      <inertia ixx="1.0" ixy="0.0" ixz="0.0" iyy="1.0" iyz="0.0" izz="1.0"/>
    </inertial>
  </link>
  <link name="link_1">
    <visual>
      <origin rpy="0 0 0" xyz="0 0 0"/>
      <geometry>
        <mesh filename="package://phantomx_arm_description/meshes/visual/shoulder_link.stl" scale="0.01 0.01 0.01"/>
      </geometry>
      <material name="">
        <color rgba="0.15 0.15 0.15 1.0"/>
      </material>
    </visual>
    <collision>
      <origin rpy="0 0 0" xyz="0 0 0"/>
      <geometry>
        <mesh filename="package://phantomx_arm_description/meshes/collision/shoulder_link.stl" scale="0.01 0.01 0.01"/>
      </geometry>
    </collision>
    <inertial>
      <origin rpy="0 0 0" xyz="0 0 0"/>
      <mass value="1"/>
      <inertia ixx="1.0" ixy="0.0" ixz="0.0" iyy="1.0" iyz="0.0" izz="1.0"/>
    </inertial>
  </link>
  <link name="link_2">
    <visual>
      <origin rpy="0 0 0" xyz="0 0 0"/>
      <geometry>
        <mesh filename="package://phantomx_arm_description/meshes/visual/bicep_link.stl" scale="0.01 0.01 0.01"/>
      </geometry>
      <material name="">
        <color rgba="0.15 0.15 0.15 1.0"/>
      </material>
    </visual>
    <collision>
      <origin rpy="0 0 0" xyz="0 0 0"/>
      <geometry>
        <mesh filename="package://phantomx_arm_description/meshes/collision/bicep_link.stl" scale="0.01 0.01 0.01"/>
      </geometry>
    </collision>
    <inertial>
      <origin rpy="0 0 0" xyz="0 0 0"/>
      <mass value="1"/>
      <inertia ixx="1.0" ixy="0.0" ixz="0.0" iyy="1.0" iyz="0.0" izz="1.0"/>
    </inertial>
  </link>
  <link name="link_3">
    <visual>
      <origin rpy="0 0 0" xyz="0 0 0"/>
      <geometry>
        <mesh filename="package://phantomx_arm_description/meshes/visual/bicep_link.stl" scale="0.01 0.01 0.01"/>
      </geometry>
      <material name="">
        <color rgba="0.15 0.15 0.15 1.0"/>
      </material>
    </visual>
    <collision>
      <origin rpy="0 0 0" xyz="0 0 0"/>
      <geometry>
        <mesh filename="package://phantomx_arm_description/meshes/collision/bicep_link.stl" scale="0.01 0.01 0.01"/>
      </geometry>
    </collision>
    <inertial>
      <origin rpy="0 0 0" xyz="0 0 0"/>
      <mass value="1"/>
      <inertia ixx="1.0" ixy="0.0" ixz="0.0" iyy="1.0" iyz="0.0" izz="1.0"/>
    </inertial>
  </link>
  <link name="link_4">
    <visual>
      <origin rpy="0.0 3.14159 -3.14159" xyz="-0.0118 0.033 0.0"/>
      <geometry>
        <mesh filename="package://phantomx_arm_description/meshes/visual/wrist_link.stl" scale="0.01 0.01 0.01"/>
      </geometry>
      <material name="">
        <color rgba="0.15 0.15 0.15 1.0"/>
      </material>
    </visual>
    <collision>
      <origin rpy="0 0 0" xyz="0 0 0"/>
      <geometry>
        <mesh filename="package://phantomx_arm_description/meshes/collision/wrist_link.stl" scale="0.01 0.01 0.01"/>
      </geometry>
    </collision>
    <inertial>
      <origin rpy="0 0 0" xyz="0 0 0"/>
      <mass value="1"/>
      <inertia ixx="1.0" ixy="0.0" ixz="0.0" iyy="1.0" iyz="0.0" izz="1.0"/>
    </inertial>
  </link>
  <link name="link_5">
    <visual>
      <origin rpy="0 0 0" xyz="-0.0115 0.013 -0.005"/>
      <geometry>
        <mesh filename="package://phantomx_arm_description/meshes/visual/guide_rail_fixed_link.stl" scale="0.01 0.01 0.01"/>
      </geometry>
      <material name="">
        <color rgba="0.15 0.15 0.15 1.0"/>
      </material>
    </visual>
    <collision>
      <origin rpy="0 0 0" xyz="0 0 0"/>
      <geometry>
        <mesh filename="package://phantomx_arm_description/meshes/collision/guide_rail_fixed_link.stl" scale="0.01 0.01 0.01"/>
      </geometry>
    </collision>
    <inertial>
      <origin rpy="0 0 0" xyz="0 0 0"/>
      <mass value="1"/>
      <inertia ixx="1.0" ixy="0.0" ixz="0.0" iyy="1.0" iyz="0.0" izz="1.0"/>
    </inertial>
  </link>
  <link name="link_6">
    <visual>
      <origin rpy="0 0 0" xyz="-0.015 -0.005 0.005"/>
      <geometry>
        <mesh filename="package://phantomx_arm_description/meshes/visual/gripper_hand_fixed_link.stl" scale="0.01 0.01 0.01"/>
      </geometry>
      <material name="">
        <color rgba="0.15 0.15 0.15 1.0"/>
      </material>
    </visual>
    <collision>
      <origin rpy="0 0 0" xyz="0 0 0"/>
      <geometry>
        <mesh filename="package://phantomx_arm_description/meshes/collision/gripper_hand_fixed_link.stl" scale="0.01 0.01 0.01"/>
      </geometry>
    </collision>
    <inertial>
      <origin rpy="0 0 0" xyz="0 0 0"/>
      <mass value="1"/>
      <inertia ixx="1.0" ixy="0.0" ixz="0.0" iyy="1.0" iyz="0.0" izz="1.0"/>
    </inertial>
  </link>
  <link name="link_7">
    <visual>
      <origin rpy="0 0 0" xyz="-0.015 -0.005 0.005"/>
      <geometry>
        <mesh filename="package://phantomx_arm_description/meshes/visual/gripper_hand_fixed_link.stl" scale="0.01 0.01 0.01"/>
      </geometry>
      <material name="">
        <color rgba="0.15 0.15 0.15 1.0"/>
      </material>
    </visual>
    <collision>
      <origin rpy="0 0 0" xyz="0 0 0"/>
      <geometry>
        <mesh filename="package://phantomx_arm_description/meshes/collision/gripper_hand_fixed_link.stl" scale="0.01 0.01 0.01"/>
      </geometry>
    </collision>
    <inertial>
      <origin rpy="0 0 0" xyz="0 0 0"/>
      <mass value="1"/>
      <inertia ixx="1.0" ixy="0.0" ixz="0.0" iyy="1.0" iyz="0.0" izz="1.0"/>
    </inertial>
  </link>
  <joint name="arm_base_joint" type="fixed">
    <origin rpy="0.0 0.0 -1.570795" xyz="0.145 0.002 0.002"/>
    <parent link="plate_top_link"/>
    <child link="arm_base_link"/>
    <axis xyz="0 1 0"/>
  </joint>
  <joint name="joint_1" type="revolute">
    <origin rpy="1.570795 6.28318 3.14159" xyz="0.00125 -0.0325 0.0875"/>
    <parent link="arm_base_link"/>
    <child link="link_1"/>
    <axis xyz="0 1 0"/>
    <limit effort="0" lower="-2.617" upper="2.617" velocity="0.785"/>
  </joint>
  <joint name="joint_2" type="revolute">
    <origin rpy="0 0.0 0" xyz="0.0 0.0415 0.0"/>
    <parent link="link_1"/>
    <child link="link_2"/>
    <axis xyz="0 0 1"/>
    <limit effort="0" lower="-2.617" upper="2.617" velocity="1.571"/>
  </joint>
  <joint name="joint_3" type="revolute">
    <origin rpy="0 0 0" xyz="0.0 0.1067 0.0"/>
    <parent link="link_2"/>
    <child link="link_3"/>
    <axis xyz="0 0 1"/>
    <limit effort="0" lower="-2.617" upper="2.617" velocity="1.571"/>
  </joint>
  <joint name="joint_4" type="revolute">
    <origin rpy="6.28318 6.28318 0" xyz="0.0 0.1067 0.0"/>
    <parent link="link_3"/>
    <child link="link_4"/>
    <axis xyz="0 0 1"/>
    <limit effort="0" lower="-1.745" upper="1.745" velocity="1.571"/>
  </joint>
  <joint name="joint_5" type="fixed">
    <origin rpy="-1.570795 -1.570795 0.0" xyz="0.0 0.07 0.0"/>
    <parent link="link_4"/>
    <child link="link_5"/>
    <axis xyz="0 1 0"/>
    <limit effort="0" lower="-0.31" upper="0.1" velocity="0.5"/>
  </joint>
  <joint name="joint_6" type="prismatic">
    <origin rpy="-4.712385 6.28318 1.570795" xyz="0.035 0.0 0.0"/>
    <parent link="link_5"/>
    <child link="link_6"/>
    <axis xyz="0 0 1"/>
    <limit effort="0" lower="-0.31" upper="0.1" velocity="0.5"/>
  </joint>
  <joint name="joint_7" type="prismatic">
    <origin rpy="-4.712385 6.28318 -1.570795" xyz="-0.035 0.0 0.0"/>
    <parent link="link_5"/>
    <child link="link_7"/>
    <axis xyz="0 0 1"/>
    <limit effort="0" lower="-0.31" upper="0.1" velocity="0.5"/>
  </joint>
</robot>
