<?xml version="1.0" encoding="UTF-8"?>
<robot xmlns:xacro="http://ros.org/wiki/xacro">
   <property name="M_PI" value="3.14159"/>
   <property name="M_SCALE" value="0.01"/>
   <xacro:include filename="$(find phantomx_arm_description)/urdf/common_materials.xacro" />

   <!--link name="plate_top_link"/-->
   <!--joint name="fixed" type="fixed">
      <parent link="plate_top_link" />
      <child link="ph_base_link" />
   </joint-->

   <xacro:macro name="phantomx_arm" params="prefix">
      <!-- links -->
      <link name="${prefix}arm_base_link">
         <visual>
            <origin xyz="${M_SCALE*10} ${M_SCALE*10} ${M_SCALE*0}" rpy="${M_PI*0} ${M_PI*0} ${M_PI}" />
            <geometry>
               <mesh filename="package://phantomx_arm_description/meshes/visual/base_link.stl" scale="${M_SCALE} ${M_SCALE} ${M_SCALE}"/>
            </geometry>
	    <xacro:material_black />
         </visual>
         <collision> 
            <origin xyz="0 0 0" rpy="0 0 0" />
            <geometry>
               <mesh filename="package://phantomx_arm_description/meshes/collision/base_link.stl" scale="${M_SCALE} ${M_SCALE} ${M_SCALE}"/>
            </geometry>
         </collision>
         <inertial>
            <origin xyz="0 0 0" rpy="0 0 0" />
            <mass value="1" />
            <inertia ixx="1.0" ixy="0.0" ixz="0.0" iyy="1.0" iyz="0.0" izz="1.0" />
         </inertial>
      </link>
      <link name="${prefix}link_1">
         <visual>
            <origin xyz="0 0 0" rpy="0 0 0" />
            <geometry>
               <mesh filename="package://phantomx_arm_description/meshes/visual/shoulder_link.stl" scale="${M_SCALE} ${M_SCALE} ${M_SCALE}"/>
            </geometry>
            <xacro:material_black />
         </visual>
         <collision>
            <origin xyz="0 0 0" rpy="0 0 0" />
            <geometry>
               <mesh filename="package://phantomx_arm_description/meshes/collision/shoulder_link.stl" scale="${M_SCALE} ${M_SCALE} ${M_SCALE}"/>
            </geometry>
         </collision>
         <inertial>
            <origin xyz="0 0 0" rpy="0 0 0" />
            <mass value="1" />
            <inertia ixx="1.0" ixy="0.0" ixz="0.0" iyy="1.0" iyz="0.0" izz="1.0" />
         </inertial>
      </link>
      <link name="${prefix}link_2">
         <visual>with
            <origin xyz="0 0 0" rpy="0 0 0" />
            <geometry>
               <mesh filename="package://phantomx_arm_description/meshes/visual/bicep_link.stl" scale="${M_SCALE} ${M_SCALE} ${M_SCALE}"/>
            </geometry>
            <xacro:material_black />
         </visual>
         <collision>
            <origin xyz="0 0 0" rpy="0 0 0" />
            <geometry>
               <mesh filename="package://phantomx_arm_description/meshes/collision/bicep_link.stl" scale="${M_SCALE} ${M_SCALE} ${M_SCALE}"/>
            </geometry>
         </collision>
         <inertial>
            <origin xyz="0 0 0" rpy="0 0 0" />
            <mass value="1" />
            <inertia ixx="1.0" ixy="0.0" ixz="0.0" iyy="1.0" iyz="0.0" izz="1.0" />
         </inertial>
      </link>
      <link name="${prefix}link_3">
         <visual>
            <origin xyz="0 0 0" rpy="0 0 0" />
            <geometry>
               <mesh filename="package://phantomx_arm_description/meshes/visual/bicep_link.stl" scale="${M_SCALE} ${M_SCALE} ${M_SCALE}"/>
            </geometry>
           <xacro:material_black />
         </visual>
         <collision>
            <origin xyz="0 0 0" rpy="0 0 0" />
            <geometry>
               <mesh filename="package://phantomx_arm_description/meshes/collision/bicep_link.stl" scale="${M_SCALE} ${M_SCALE} ${M_SCALE}"/>
            </geometry>
         </collision>
         <inertial>
            <origin xyz="0 0 0" rpy="0 0 0" />
            <mass value="1" />
            <inertia ixx="1.0" ixy="0.0" ixz="0.0" iyy="1.0" iyz="0.0" izz="1.0"/>
         </inertial>
      </link>
      <link name="${prefix}link_4">
         <visual>
            <origin xyz="${M_SCALE*-1.18} ${M_SCALE*3.3} ${M_SCALE*0}" rpy="${M_PI*0} ${M_PI} ${-M_PI}" />
            <geometry>
               <mesh filename="package://phantomx_arm_description/meshes/visual/wrist_link.stl" scale="${M_SCALE} ${M_SCALE} ${M_SCALE}"/>
            </geometry>
            <xacro:material_black />
         </visual>
         <collision>
            <origin xyz="0 0 0" rpy="0 0 0" />
            <geometry>
               <mesh filename="package://phantomx_arm_description/meshes/collision/wrist_link.stl" scale="${M_SCALE} ${M_SCALE} ${M_SCALE}"/>
            </geometry>
         </collision>
         <inertial>
            <origin xyz="0 0 0" rpy="0 0 0" />
            <mass value="1" />
            <inertia ixx="1.0" ixy="0.0" ixz="0.0" iyy="1.0" iyz="0.0" izz="1.0" />
         </inertial>
      </link>
      <link name="${prefix}link_5">
         <visual>
            <origin xyz="${M_SCALE*-1.15} ${M_SCALE*1.3} ${M_SCALE*-0.5}" rpy="0 0 0" />
            <geometry>
               <mesh filename="package://phantomx_arm_description/meshes/visual/guide_rail_fixed_link.stl" scale="${M_SCALE} ${M_SCALE} ${M_SCALE}"/>
            </geometry>
            <xacro:material_black />
         </visual>
         <collision>
            <origin xyz="0 0 0" rpy="0 0 0" />
            <geometry>
               <mesh filename="package://phantomx_arm_description/meshes/collision/guide_rail_fixed_link.stl" scale="${M_SCALE} ${M_SCALE} ${M_SCALE}"/>
            </geometry>
         </collision>
         <inertial>
            <origin xyz="0 0 0" rpy="0 0 0" />
            <mass value="1" />
            <inertia ixx="1.0" ixy="0.0" ixz="0.0" iyy="1.0" iyz="0.0" izz="1.0" />
         </inertial>
      </link>
      <link name="${prefix}link_6">
         <visual>
            <origin xyz="${M_SCALE*-1.5} ${M_SCALE*-0.5} ${M_SCALE*0.5}" rpy="0 0 0" />
            <geometry>
               <mesh filename="package://phantomx_arm_description/meshes/visual/gripper_hand_fixed_link.stl" scale="${M_SCALE} ${M_SCALE} ${M_SCALE}"/>
            </geometry>
            <xacro:material_black />
         </visual>
         <collision>
            <origin xyz="0 0 0" rpy="0 0 0" />
            <geometry>
               <mesh filename="package://phantomx_arm_description/meshes/collision/gripper_hand_fixed_link.stl" scale="${M_SCALE} ${M_SCALE} ${M_SCALE}"/>
            </geometry>
         </collision>
         <inertial>
            <origin xyz="0 0 0" rpy="0 0 0" />
            <mass value="1" />
            <inertia ixx="1.0" ixy="0.0" ixz="0.0" iyy="1.0" iyz="0.0" izz="1.0" />
         </inertial>
      </link>
       <link name="${prefix}link_7">
         <visual>
            <origin xyz="${M_SCALE*-1.5} ${M_SCALE*-0.5} ${M_SCALE*0.5}" rpy="0 0 0" />
            <geometry>
               <mesh filename="package://phantomx_arm_description/meshes/visual/gripper_hand_fixed_link.stl" scale="${M_SCALE} ${M_SCALE} ${M_SCALE}"/>
            </geometry>
            <xacro:material_black />
         </visual>
         <collision>
            <origin xyz="0 0 0" rpy="0 0 0" />
            <geometry>
               <mesh filename="package://phantomx_arm_description/meshes/collision/gripper_hand_fixed_link.stl" scale="${M_SCALE} ${M_SCALE} ${M_SCALE}"/>
            </geometry>
         </collision>
         <inertial>
            <origin xyz="0 0 0" rpy="0 0 0" />
            <mass value="1" />
            <inertia ixx="1.0" ixy="0.0" ixz="0.0" iyy="1.0" iyz="0.0" izz="1.0" />
         </inertial>
      </link>
      <!-- joints -->
      <joint name="${prefix}arm_base_joint" type="fixed">
         <origin xyz="${M_SCALE*14.5} ${M_SCALE*0.2} ${M_SCALE*0.2}" rpy="${M_PI*0} ${M_PI*0} ${-M_PI/2}" />
         <parent link="plate_top_link" />
         <child link="${prefix}arm_base_link"/>
         <axis xyz="0 1 0" />
      </joint>
      <joint name="${prefix}joint_1" type="revolute">
         <origin xyz="${M_SCALE*0.125} ${M_SCALE*-3.25} ${M_SCALE*8.75}" rpy="${M_PI/2} ${M_PI*2} ${M_PI}" />
         <parent link="${prefix}arm_base_link" />
         <child link="${prefix}link_1" />
         <axis xyz="0 1 0" />
         <limit lower="-2.617" upper="2.617" effort="0" velocity="0.785" />
      </joint>
      <joint name="${prefix}joint_2" type="revolute">
         <origin xyz="${M_SCALE*0} ${M_SCALE*4.15} ${M_SCALE*0}" rpy="0 ${M_PI*0} 0" />
         <parent link="${prefix}link_1" />
         <child link="${prefix}link_2" />
         <axis xyz="0 0 1" />
         <limit lower="-2.617" upper="2.617" effort="0" velocity="1.571" />
      </joint>
      <joint name="${prefix}joint_3" type="revolute">
         <origin xyz="${M_SCALE*0} ${M_SCALE*10.67} ${M_SCALE*0}" rpy="0 0 0" />
         <parent link="${prefix}link_2" />
         <child link="${prefix}link_3" />
         <axis xyz="0 0 1" />
         <limit lower="-2.617" upper="2.617" effort="0" velocity="1.571" />
      </joint>
      <joint name="${prefix}joint_4" type="revolute">
         <origin xyz="${M_SCALE*0} ${M_SCALE*10.67} ${M_SCALE*0}" rpy="${M_PI*2} ${M_PI*2} 0" />
         <parent link="${prefix}link_3" />
         <child link="${prefix}link_4" />
         <axis xyz="0 0 1" />
         <limit lower="-1.745" upper="1.745" effort="0" velocity="1.571" />
      </joint>
      <joint name="${prefix}joint_5" type="fixed">
         <origin xyz="${M_SCALE*0} ${M_SCALE*7} ${M_SCALE*0}" rpy="${-M_PI/2} ${-M_PI/2} ${M_PI*0}" />
         <parent link="${prefix}link_4" />
         <child link="${prefix}link_5" />
         <axis xyz="0 1 0" />
         <limit lower="-0.31" upper="0.1" effort="0" velocity="0.5" />
      </joint>
      <joint name="${prefix}joint_6" type="prismatic">
         <origin xyz="${M_SCALE*3.5} ${M_SCALE*0} ${M_SCALE*0}" rpy="${-M_PI*1.5} ${M_PI*2} ${M_PI/2}" />
         <parent link="${prefix}link_5" />
         <child link="${prefix}link_6" />
         <axis xyz="0 0 1" />
         <limit lower="-0.31" upper="0.1" effort="0" velocity="0.5" />
      </joint>
      <joint name="${prefix}joint_7" type="prismatic">
         <origin xyz="${M_SCALE*-3.5} ${M_SCALE*0} ${M_SCALE*0}" rpy="${-M_PI*1.5} ${M_PI*2} ${-M_PI/2}" />
         <parent link="${prefix}link_5" />
         <child link="${prefix}link_7" />
         <axis xyz="0 0 1" />
         <limit lower="-0.31" upper="0.1" effort="0" velocity="0.5" />
      </joint>
   </xacro:macro>


  <transmission name="tran1">
    <type>transmission_interface/SimpleTransmission</type>
    <joint name="joint_1"/>
    <actuator name="motor1">
      <hardwareInterface>EffortJointInterface</hardwareInterface>
      <mechanicalReduction>1</mechanicalReduction>
    </actuator>
  </transmission>

 <transmission name="tran2">
    <type>transmission_interface/SimpleTransmission</type>
    <joint name="joint_2"/>
    <actuator name="motor2">
      <hardwareInterface>EffortJointInterface</hardwareInterface>
      <mechanicalReduction>1</mechanicalReduction>
    </actuator>
  </transmission>

 <transmission name="tran3">
    <type>transmission_interface/SimpleTransmission</type>
    <joint name="joint_3"/>
    <actuator name="motor3">
      <hardwareInterface>EffortJointInterface</hardwareInterface>
      <mechanicalReduction>1</mechanicalReduction>
    </actuator>
  </transmission>

 <transmission name="tran4">
    <type>transmission_interface/SimpleTransmission</type>
    <joint name="joint_4"/>
    <actuator name="motor4">
      <hardwareInterface>EffortJointInterface</hardwareInterface>
      <mechanicalReduction>1</mechanicalReduction>
    </actuator>
  </transmission>

 <transmission name="tran5">
    <type>transmission_interface/SimpleTransmission</type>
    <joint name="joint_6"/>
    <actuator name="motor5">
      <hardwareInterface>EffortJointInterface</hardwareInterface>
      <mechanicalReduction>1</mechanicalReduction>
    </actuator>
  </transmission>

 <transmission name="tran6">
    <type>transmission_interface/SimpleTransmission</type>
    <joint name="joint_7"/>
    <actuator name="motor6">
      <hardwareInterface>EffortJointInterface</hardwareInterface>
      <mechanicalReduction>1</mechanicalReduction>
    </actuator>
  </transmission>

</robot>

